# exception happens, programming mistake. bad data send form user, resource is not avaiable
# OPEN FILE DOES NOT EXIST , OUR PROGRAM WILL CRASH


# numbers = [1, 2]
# Index Error
# print(numbers[3])
# Traceback (most recent call last):
#   File "c:\Users\ASUS\Desktop\Python\exception.py", line 6, in <module>
#     print(numbers[3])
# IndexError: list index out of range

# age = int(input("Age: "))
# Age: a
# Traceback (most recent call last):
#   File "C:\Users\ASUS\Desktop\Python\exception.py", line 13, in <module>
#     age = int(input("Age: "))
# ValueError: invalid literal for int() with base 10: 'a'


#######################################################################
